Workbook

Sheet China
C2: LSEG | D2: LSEG | I2: LSEG | L2: LSEG | M2: LSEG
C3: CNCPI=ECI (ECONOMIC) | D3: CNGDP=ECI (ECONOMIC) | H3: https://fred.stlouisfed.org/series/intdsrcnm193n | I3: aCNGBOND (ECONOMIC) | V3: fred.stlouisfed.org/series/QCNN628BIS
B4: Date | C4: GDP YoY (%) | D4: CPI YoY (%) | G4: Date | H4: Cash Rate (%) | I4: 10Y Bond Yield (%) | K4: Date | L4: CNY/USD | M4: Exports YoY (%)
B5: 42552 | C5: 6.7 | D5: 1.8 | G5: 42583 | H5: 2.9 | I5: 2.81 | K5: 42614 | L5: 6.6685 | M5: -10.4 | V5: observation_date | W5: QCNN628BIS
B6: 42644 | C6: 6.8 | D6: 2.1 | G6: 42614 | H6: 2.9 | I6: 2.77 | K6: 42644 | L6: 6.7735 | M6: -7.9 | V6: 38443 | W6: 75.8675
B7: 42736 | C7: 7 | D7: 2.5 | G7: 42644 | H7: 2.9 | I7: 2.74 | K7: 42675 | L7: 6.8837 | M7: -1.5 | V7: 38534 | W7: 77.0645
B8: 42826 | C8: 7 | D8: 1.2 | G8: 42675 | H8: 2.9 | I8: 2.94 | K8: 42705 | L8: 6.943 | M8: -6.2 | V8: 38626 | W8: 77.9195
B9: 42917 | C9: 6.9 | D9: 1.4 | G9: 42705 | H9: 2.9 | I9: 3.07 | K9: 42736 | L9: 6.8768 | M9: 6.6 | V9: 38718 | W9: 78.005
B10: 43009 | C10: 6.8 | D10: 1.9 | G10: 42736 | H10: 2.9 | I10: 3.36 | K10: 42767 | L10: 6.8665 | M10: -2.4 | V10: 38808 | W10: 79.544
B11: 43101 | C11: 6.9 | D11: 1.5 | G11: 42767 | H11: 2.9 | I11: 3.36 | K11: 42795 | L11: 6.8832 | M11: 15.4 | V11: 38899 | W11: 80.855
B12: 43191 | C12: 6.9 | D12: 1.8 | G12: 42795 | H12: 2.9 | I12: 3.31 | K12: 42826 | L12: 6.89 | M12: 6.5 | V12: 38991 | W12: 81.824
B13: 43282 | C13: 6.7 | D13: 2.1 | G13: 42826 | H13: 2.9 | I13: 3.48 | K13: 42856 | L13: 6.8098 | M13: 7.6 | V13: 39083 | W13: 82.1375
B14: 43374 | C14: 6.5 | D14: 2.5 | G14: 42856 | H14: 2.9 | I14: 3.67 | K14: 42887 | L14: 6.7793 | M14: 10.3 | V14: 39173 | W14: 84.218
B15: 43466 | C15: 6.4 | D15: 1.7 | G15: 42887 | H15: 2.9 | I15: 3.58 | K15: 42917 | L15: 6.724 | M15: 6.4 | V15: 39264 | W15: 86.498
B16: 43556 | C16: 6.1 | D16: 2.5 | G16: 42917 | H16: 2.9 | I16: 3.63 | K16: 42948 | L16: 6.5888 | M16: 4.9 | V16: 39356 | W16: 89.1486
B17: 43647 | C17: 6 | D17: 2.8 | G17: 42948 | H17: 2.9 | I17: 3.67 | K17: 42979 | L17: 6.6533 | M17: 7.9 | V17: 39448 | W17: 89.8611
... B44: 46113 | C44: 4.3 | D44: 1.2 | G44: 43770 | H44: 2.9 | I44: 3.19 | K44: 43800 | L44: 6.9618 | M44: 7.9 | V44: 41913 | W44: 109.1557
G45: 43800 | H45: 2.9 | I45: 3.17 | K45: 43831 | L45: 6.9364 | M45: -2.9 | V45: 42005 | W45: 107.8162
G46: 43831 | H46: 2.9 | I46: 3.05 | K46: 43862 | L46: 6.9906 | M46: -40.6 | V46: 42095 | W46: 107.5882
G47: 43862 | H47: 2.9 | I47: 2.8 | K47: 43891 | L47: 7.0808 | M47: -6.9 | V47: 42186 | W47: 108.2437
G48: 43891 | H48: 2.9 | I48: 2.66 | K48: 43922 | L48: 7.06 | M48: 3.1 | V48: 42278 | W48: 108.8422
G49: 43922 | H49: 2.9 | I49: 2.51 | K49: 43952 | L49: 7.1348 | M49: -3.5 | V49: 42370 | W49: 111.5332
G50: 43952 | H50: 2.9 | I50: 2.71 | K50: 43983 | L50: 7.0651 | M50: 0.2 | V50: 42461 | W50: 113.8325
G51: 43983 | H51: 2.9 | I51: 2.9 | K51: 44013 | L51: 6.9744 | M51: 6.8 | V51: 42552 | W51: 116.4238
G52: 44013 | H52: 2.9 | I52: 2.97 | K52: 44044 | L52: 6.8474 | M52: 9.1 | V52: 42644 | W52: 119.1975
G53: 44044 | H53: 2.9 | I53: 3.05 | K53: 44075 | L53: 6.7896 | M53: 9.4 | V53: 42736 | W53: 120.6209
G54: 44075 | H54: 2.9 | I54: 3.15 | K54: 44105 | L54: 6.6919 | M54: 10.9 | V54: 42826 | W54: 122.9931
G55: 44105 | H55: 2.9 | I55: 3.19 | K55: 44136 | L55: 6.576 | M55: 20.6 | V55: 42917 | W55: 124.38
G56: 44136 | H56: 2.9 | I56: 3.28 | K56: 44166 | L56: 6.525 | M56: 18.1 | V56: 43009 | W56: 125.1464
... G89: 45139 | H89: 2.9 | I89: 2.59 | K89: 45170 | L89: 7.301 | M89: -6.8 | V89: 46023 | W89: 113.9785
G90: 45170 | H90: 2.9 | I90: 2.71 | K90: 45200 | L90: 7.3158 | M90: -6.6
G91: 45200 | H91: 2.9 | I91: 2.71 | K91: 45231 | L91: 7.136 | M91: 0.7
G92: 45231 | H92: 2.9 | I92: 2.69 | K92: 45261 | L92: 7.0978 | M92: 2.3
G93: 45261 | H93: 2.9 | I93: 2.58 | K93: 45292 | L93: 7.1673 | M93: 7.7
G94: 45292 | H94: 2.9 | I94: 2.44 | K94: 45323 | L94: 7.1877 | M94: 6.3
G95: 45323 | H95: 2.9 | I95: 2.36 | K95: 45352 | L95: 7.2203 | M95: -7.6
G96: 45352 | H96: 2.9 | I96: 2.3 | K96: 45383 | L96: 7.2401 | M96: 1.3
G97: 45383 | H97: 2.9 | I97: 2.31 | K97: 45413 | L97: 7.2415 | M97: 7.4
G98: 45413 | H98: 2.9 | I98: 2.32 | K98: 45444 | L98: 7.2672 | M98: 8.5
G99: 45444 | H99: 2.9 | I99: 2.21 | K99: 45474 | L99: 7.2193 | M99: 6.9
...

Sheet Emerging
A2: LSEG | R2: Nominal Emerging Market Economies U.S. Dollar Index
B3: INCAPA=ECI (ECONOMIC) | C3: MXACUR=ECI (ECONOMIC) | D3: ZAGDPY=ECI (ECONOMIC) | E3: IDGDP=ECI (ECONOMIC) | R3: observation_date | S3: TWEXEMEGSMTH | U3: https://fred.stlouisfed.org/series/TWEXEMEGSMTH?utm_
A4: Date | B4: India GDP (%) | C4: Mexico GDP (%) | D4: South Africa GDP (%) | E4: Indonesia GDP (%) | R4: 44409 | S4: 123.7116
A5: 46113 | B5: -0.5 | C5: 1.65 | D5: 1.9 | E5: 5.29 | R5: 44440 | S5: 123.464
A6: 46023 | B6: 0.7 | C6: -3.61 | D6: 0.8 | E6: 5.61 | R6: 44470 | S6: 124.3734
A7: 45931 | B7: -1.3 | C7: 1.54 | D7: 2.1 | E7: 5.39 | R7: 44501 | S7: 124.8764
A8: 45839 | B8: -1.3 | C8: 0.2 | D8: 0.7 | E8: 5.04 | R8: 44531 | S8: 125.298
A9: 45748 | B9: -0.3 | C9: -0.99 | D9: 0.9 | E9: 5.12 | R9: 44562 | S9: 124.3316
A10: 45658 | B10: 1.3 | C10: -3.21 | D10: 0.8 | E10: 4.87 | R10: 44593 | S10: 124.0418
A11: 45566 | B11: -1.1 | C11: 2.47 | D11: 0.4 | E11: 5.02 | R11: 44621 | S11: 124.7618
A12: 45474 | B12: -2.2 | C12: -0.54 | D12: 0.4 | E12: 4.95 | R12: 44652 | S12: 124.5443
A13: 45383 | B13: -0.5 | C13: -0.16 | D13: 0.5 | E13: 5.05 | R13: 44682 | S13: 126.8992
R14: 44713 | S14: 127.1571
A15: LSEG | R15: 44743 | S15: 129.7725
B16: INCPIY=ECI (ECONOMIC) | C16: BRCPIY=ECI (ECONOMIC) | D16: MXCPIA=ECI (ECONOMIC) | E16: ZACPIY=ECI (ECONOMIC) | F16: IDCPI=ECI (ECONOMIC) | R16: 44774 | S16: 129.023
A17: Date | B17: India CPI (%) | C17: Brazil CPI (%) | D17: Mexico CPI (%) | E17: South Africa CPI (%) | F17: Indonesia CPI (%) | R17: 44805 | S17: 131.6451
A18: 44378 | B18: 5.07 | C18: 9.64 | D18: 5.8 | E18: 4.8 | F18: 1.57 | R18: 44835 | S18: 133.662
A19: 44470 | B19: 5.05 | C19: 10.49 | D19: 6.99 | E19: 5.43 | F19: 1.76 | R19: 44866 | S19: 131.8784
A20: 44562 | B20: 6.35 | C20: 10.74 | D20: 7.27 | E20: 5.7 | F20: 2.23 | R20: 44896 | S20: 129.7434
A21: 44652 | B21: 7.25 | C21: 11.92 | D21: 7.77 | E21: 6.63 | F21: 3.7 | R21: 44927 | S21: 126.6445
A22: 44743 | B22: 6.99 | C22: 8.66 | D22: 8.52 | E22: 7.67 | F22: 5.13 | R22: 44958 | S22: 126.758
A23: 44835 | B23: 6.13 | C23: 6.05 | D23: 8.01 | E23: 7.4 | F23: 5.48 | R23: 44986 | S23: 127.0148
A24: 44927 | B24: 6.2 | C24: 5.34 | D24: 7.46 | E24: 6.97 | F24: 5.16 | R24: 45017 | S24: 126.1816
A25: 45017 | B25: 4.61 | C25: 3.76 | D25: 5.72 | E25: 6.13 | F25: 3.99 | R25: 45047 | S25: 126.0915
A26: 45108 | B26: 6.47 | C26: 4.6 | D26: 4.63 | E26: 4.97 | F26: 2.95 | R26: 45078 | S26: 125.5637
A27: 45200 | B27: 5.35 | C27: 4.71 | D27: 4.41 | E27: 5.57 | F27: 2.81 | R27: 45108 | S27: 124.8058
A28: 45292 | B28: 5.05 | C28: 4.31 | D28: 4.57 | E28: 5.43 | F28: 2.79 | R28: 45139 | S28: 126.3969
A29: 45383 | B29: 4.94 | C29: 3.95 | D29: 4.77 | E29: 5.17 | F29: 2.78 | R29: 45170 | S29: 127.9809
... A38: 46204 | B38: 4.45 | C38: 4.44 | D38: 3.12 | E38: 4.3 | F38: 3.04 | R38: 45444 | S38: 132.1008
R39: 45474 | S39: 132.0201
A40: MSCI EM | R40: 45505 | S40: 132.808
B41: .dMIEF00000PUS (TRDPRC_1) | C41: LSEG | R41: 45536 | S41: 132.7205
A42: Date | B42: MSCI EM Index | R42: 45566 | S42: 133.7709
A43: 44440 | B43: 1253.1 | R43: 45597 | S43: 136.5813
A44: 44470 | B44: 1264.75 | R44: 45627 | S44: 137.4717
A45: 44501 | B45: 1212.42 | R45: 45658 | S45: 138.3438
A46: 44531 | B46: 1232.01 | R46: 45689 | S46: 137.6507
A47: 44562 | B47: 1208.23 | R47: 45717 | S47: 137.1056
A48: 44593 | B48: 1171.31 | R48: 45748 | S48: 136.8608
A49: 44621 | B49: 1141.79 | R49: 45778 | S49: 133.7754
...

Sheet Australia
B1: LSEG 7/9 | C1: LSEG 7/9 | M1: LSEG 2/9 | N1: LSEG 2/9 | Q1: LSEG 2/9 | R1: LSEG 2/9 | AB1: LSEG | AG1: https://www.rba.gov.au/statistics/tables/ | AO1: AUD unemployment | AP1: https://www.abs.gov.au/statistics/labour/employment-and-unemployment/labour-force-australia/latest-release#data-downloads
AB3: aAUCBIRAR (ECONOMIC)
A4: Date | B4: GDP Y/Y | C4: CPI Y/Y | L4: Date | M4: S&P ASX200 | N4: AUD/USD | P4: Date | Q4: S&P ASX200 | R4: AUD/USD | AA4: Date | AB4: 10Y Cashrate | AE4: Date | AF4: RBA Cash Rate (%) | AG4: 10Y ACGB Yield (%) | AI4: Date | AJ4: Fed Funds Rate (%) | AK4: SPY Close ($) | AO4: > Unemployment rate looked for full-time work ; Persons ;
A5: 46113 | B5: 2.1 | C5: 4 | L5: 44440 | M5: 7332.2 | N5: 0.7226 | P5: 44440 | Q5: =M5/$M$5*100 -> 100 | R5: =N5/$N$5*100 -> 100 | AA5: 46235 | AB5: 4.35 | AE5: 42583 | AF5: 1.5 | AG5: 1.892 | AI5: 42614 | AJ5: 0.4 | AK5: 216.3 | AO5: Percent
A6: 46023 | B6: 2.5 | C6: 4.1 | L6: 44470 | M6: 7323.7 | N6: 0.7521 | P6: 44470 | Q6: =M6/$M$5*100 -> 99.884073 | R6: =N6/$N$5*100 -> 104.08248 | AA6: 46174 | AB6: 4.35 | AE6: 42614 | AF6: 1.5 | AG6: 2.004 | AI6: 42644 | AJ6: 0.4 | AK6: 212.55 | AO6: Trend
A7: 45931 | B7: 2.6 | C7: 3.6 | L7: 44501 | M7: 7256 | N7: 0.7123 | P7: 44501 | Q7: =M7/$M$5*100 -> 98.960748 | R7: =N7/$N$5*100 -> 98.574592 | AA7: 46143 | AB7: 4.35 | AE7: 42644 | AF7: 1.5 | AG7: 2.231 | AI7: 42675 | AJ7: 0.41 | AK7: 220.38 | AO7: PERCENT
A8: 45839 | B8: 2.1 | C8: 3.2 | L8: 44531 | M8: 7444.6 | N8: 0.726 | P8: 44531 | Q8: =M8/$M$5*100 -> 101.53296 | R8: =N8/$N$5*100 -> 100.47052 | AA8: 46082 | AB8: 4.1 | AE8: 42675 | AF8: 1.5 | AG8: 2.535 | AI8: 42705 | AJ8: 0.54 | AK8: 223.53 | AO8: Month
A9: 45748 | B9: 1.9 | C9: 2.1 | L9: 44565 | M9: 6971.6 | N9: 0.7064 | P9: 44565 | Q9: =M9/$M$5*100 -> 95.081967 | R9: =N9/$N$5*100 -> 97.758096 | AA9: 46054 | AB9: 3.85 | AE9: 42705 | AF9: 1.5 | AG9: 2.799 | AI9: 42736 | AJ9: 0.65 | AK9: 227.53 | AO9: 1
A10: 45658 | B10: 1.3 | C10: 2.4 | L10: 44593 | M10: 7049.1 | N10: 0.7262 | P10: 44593 | Q10: =M10/$M$5*100 -> 96.138949 | R10: =N10/$N$5*100 -> 100.4982 | AA10: 45992 | AB10: 3.6 | AE10: 42736 | AF10: 1.5 | AG10: 2.711 | AI10: 42767 | AJ10: 0.66 | AK10: 236.47 | AO10: 28522
A11: 45566 | B11: 1.2 | C11: 2.4 | L11: 44621 | M11: 7499.6 | N11: 0.748 | P11: 44621 | Q11: =M11/$M$5*100 -> 102.28308 | R11: =N11/$N$5*100 -> 103.51508 | AA11: 45962 | AB11: 3.6 | AE11: 42767 | AF11: 1.5 | AG11: 2.738 | AI11: 42795 | AJ11: 0.79 | AK11: 235.74 | AO11: 46204
A12: 45474 | B12: 0.8 | C12: 2.9 | L12: 44652 | M12: 7435 | N12: 0.7063 | P12: 44652 | Q12: =M12/$M$5*100 -> 101.40203 | R12: =N12/$N$5*100 -> 97.744257 | AA12: 45931 | AB12: 3.6 | AE12: 42795 | AF12: 1.5 | AG12: 2.804 | AI12: 42826 | AJ12: 0.9 | AK12: 238.08 | AO12: 582
A13: 45383 | B13: 0.9 | C13: 3.8 | L13: 44683 | M13: 7211.2 | N13: 0.7173 | P13: 44683 | Q13: =M13/$M$5*100 -> 98.349745 | R13: =N13/$N$5*100 -> 99.266538 | AA13: 45901 | AB13: 3.6 | AE13: 42826 | AF13: 1.5 | AG13: 2.557 | AI13: 42856 | AJ13: 0.91 | AK13: 241.44 | AN13: Date | AO13: Australia Unemployment Rate (%)
A14: 45292 | B14: 1.1 | C14: 3.6 | L14: 44713 | M14: 6568.1 | N14: 0.6901 | P14: 44713 | Q14: =M14/$M$5*100 -> 89.578844 | R14: =N14/$N$5*100 -> 95.502353 | AA14: 45870 | AB14: 3.6 | AE14: 42856 | AF14: 1.5 | AG14: 2.548 | AI14: 42887 | AJ14: 1.04 | AK14: 241.8 | AN14: 42401 | AO14: 5.9
A15: 45200 | B15: 1.3 | C15: 4.1 | L15: 44743 | M15: 6945.2 | N15: 0.6985 | P15: 44743 | Q15: =M15/$M$5*100 -> 94.721912 | R15: =N15/$N$5*100 -> 96.664821 | AA15: 45839 | AB15: 3.85 | AE15: 42887 | AF15: 1.5 | AG15: 2.421 | AI15: 42917 | AJ15: 1.15 | AK15: 246.77 | AN15: 42430 | AO15: 5.9
A16: 45108 | B16: 2.2 | C16: 5.3 | L16: 44774 | M16: 6986.8 | N16: 0.6839 | P16: 44774 | Q16: =M16/$M$5*100 -> 95.289272 | R16: =N16/$N$5*100 -> 94.64434 | AA16: 45778 | AB16: 3.85 | AE16: 42917 | AF16: 1.5 | AG16: 2.664 | AI16: 42948 | AJ16: 1.16 | AK16: 247.49 | AN16: 42461 | AO16: 5.8
A17: 45017 | B17: 2.2 | C17: 6 | L17: 44805 | M17: 6474.2 | N17: 0.6402 | P17: 44805 | Q17: =M17/$M$5*100 -> 88.298192 | R17: =N17/$N$5*100 -> 88.596734 | AA17: 45748 | AB17: 4.1 | AE17: 42948 | AF17: 1.5 | AG17: 2.626 | AI17: 42979 | AJ17: 1.15 | AK17: 251.23 | AN17: 42491 | AO17: 5.8
A18: 44927 | B18: 2.8 | C18: 7 | L18: 44837 | M18: 6863.5 | N18: 0.6397 | P18: 44837 | Q18: =M18/$M$5*100 -> 93.607648 | R18: =N18/$N$5*100 -> 88.527539 | AA18: 45689 | AB18: 4.1 | AE18: 42979 | AF18: 1.5 | AG18: 2.71 | AI18: 43009 | AJ18: 1.15 | AK18: 257.15 | AN18: 42522 | AO18: 5.7
A19: 44835 | B19: 3.3 | C19: 7.9 | L19: 44866 | M19: 7284.2 | N19: 0.6786 | P19: 44866 | Q19: =M19/$M$5*100 -> 99.345353 | R19: =N19/$N$5*100 -> 93.910877 | AA19: 45627 | AB19: 4.35 | AE19: 43009 | AF19: 1.5 | AG19: 2.768 | AI19: 43040 | AJ19: 1.16 | AK19: 265.01 | AN19: 42552 | AO19: 5.7
A20: 44743 | B20: 6.1 | C20: 7.3 | L20: 44896 | M20: 7038.7 | N20: 0.6813 | P20: 44896 | Q20: =M20/$M$5*100 -> 95.997109 | R20: =N20/$N$5*100 -> 94.284528 | AA20: 45597 | AB20: 4.35 | AE20: 43040 | AF20: 1.5 | AG20: 2.565 | AI20: 43070 | AJ20: 1.3 | AK20: 266.86 | AN20: 42583 | AO20: 5.7
A21: 44652 | B21: 3.8 | C21: 6.2 | L21: 44929 | M21: 7476.7 | N21: 0.7054 | P21: 44929 | Q21: =M21/$M$5*100 -> 101.97076 | R21: =N21/$N$5*100 -> 97.619707 | AA21: 45536 | AB21: 4.35 | AE21: 43070 | AF21: 1.5 | AG21: 2.583 | AI21: 43101 | AJ21: 1.41 | AK21: 281.9 | AN21: 42614 | AO21: 5.8
A22: 44562 | B22: 3.6 | C22: 5.1 | L22: 44958 | M22: 7258.4 | N22: 0.6728 | P22: 44958 | Q22: =M22/$M$5*100 -> 98.993481 | R22: =N22/$N$5*100 -> 93.10822 | AA22: 45505 | AB22: 4.35 | AE22: 43101 | AF22: 1.5 | AG22: 2.747 | AI22: 43132 | AJ22: 1.42 | AK22: 271.65 | AN22: 42644 | AO22: 5.8
A23: 44470 | B23: 4.9 | C23: 3.5 | L23: 44986 | M23: 7177.8 | N23: 0.6685 | P23: 44986 | Q23: =M23/$M$5*100 -> 97.89422 | R23: =N23/$N$5*100 -> 92.513147 | AA23: 45444 | AB23: 4.35 | AE23: 43132 | AF23: 1.5 | AG23: 2.845 | AI23: 43160 | AJ23: 1.51 | AK23: 263.15 | AN23: 42675 | AO23: 5.9
A24: 44378 | B24: 4.7 | C24: 3.1 | L24: 45019 | M24: 7309.2 | N24: 0.6607 | P24: 45019 | Q24: =M24/$M$5*100 -> 99.686315 | R24: =N24/$N$5*100 -> 91.433712 | AA24: 45413 | AB24: 4.35 | AE24: 43160 | AF24: 1.5 | AG24: 2.713 | AI24: 43191 | AJ24: 1.69 | AK24: 264.51 | AN24: 42705 | AO24: 6
A25: 44287 | B25: 10.2 | C25: 3.8 | L25: 45047 | M25: 7091.3 | N25: 0.65 | P25: 45047 | Q25: =M25/$M$5*100 -> 96.714492 | R25: =N25/$N$5*100 -> 89.952948 | AA25: 45352 | AB25: 4.35 | AE25: 43191 | AF25: 1.5 | AG25: 2.734 | AI25: 43221 | AJ25: 1.7 | AK25: 270.94 | AN25: 42736 | AO25: 6
G26: 40 | L26: 45078 | M26: 7203.3 | N26: 0.6666 | P26: 45078 | Q26: =M26/$M$5*100 -> 98.242001 | R26: =N26/$N$5*100 -> 92.250208 | AA26: 45323 | AB26: 4.35 | AE26: 43221 | AF26: 1.5 | AG26: 2.79 | AI26: 43252 | AJ26: 1.82 | AK26: 271.28 | AN26: 42767 | AO26: 5.9
L27: 45110 | M27: 7410.4 | N27: 0.672 | P27: 45110 | Q27: =M27/$M$5*100 -> 101.06653 | R27: =N27/$N$5*100 -> 92.997509 | AA27: 45261 | AB27: 4.35 | AE27: 43252 | AF27: 1.5 | AG27: 2.697 | AI27: 43282 | AJ27: 1.91 | AK27: 281.33 | AN27: 42795 | AO27: 5.9
L28: 45139 | M28: 7305.3 | N28: 0.6483 | P28: 45139 | Q28: =M28/$M$5*100 -> 99.633125 | R28: =N28/$N$5*100 -> 89.717686 | AA28: 45231 | AB28: 4.35 | AE28: 43282 | AF28: 1.5 | AG28: 2.637 | AI28: 43313 | AJ28: 1.91 | AK28: 290.31 | AN28: 42826 | AO28: 5.8
L29: 45170 | M29: 7048.6 | N29: 0.6434 | P29: 45170 | Q29: =M29/$M$5*100 -> 96.13213 | R29: =N29/$N$5*100 -> 89.039579 | AA29: 45200 | AB29: 4.1 | AE29: 43313 | AF29: 1.5 | AG29: 2.59 | AI29: 43344 | AJ29: 1.95 | AK29: 290.72 | AN29: 42856 | AO29: 5.7
L30: 45201 | M30: 6780.7 | N30: 0.6336 | P30: 45201 | Q30: =M30/$M$5*100 -> 92.478383 | R30: =N30/$N$5*100 -> 87.683366 | AA30: 45170 | AB30: 4.1 | AE30: 43344 | AF30: 1.5 | AG30: 2.631 | AI30: 43374 | AJ30: 2.19 | AK30: 270.63 | AN30: 42887 | AO30: 5.6
L31: 45231 | M31: 7087.3 | N31: 0.6605 | P31: 45231 | Q31: =M31/$M$5*100 -> 96.659938 | R31: =N31/$N$5*100 -> 91.406034 | AA31: 45139 | AB31: 4.1 | AE31: 43374 | AF31: 1.5 | AG31: 2.682 | AI31: 43405 | AJ31: 2.2 | AK31: 275.65 | AN31: 42917 | AO31: 5.5
L32: 45261 | M32: 7590.8 | N32: 0.681 | P32: 45261 | Q32: =M32/$M$5*100 -> 103.52691 | R32: =N32/$N$5*100 -> 94.243011 | AA32: 45108 | AB32: 4.1 | AE32: 43405 | AF32: 1.5 | AG32: 2.683 | AI32: 43435 | AJ32: 2.27 | AK32: 249.92 | AN32: 42948 | AO32: 5.5
L33: 45293 | M33: 7680.7 | N33: 0.6565 | P33: 45293 | Q33: =M33/$M$5*100 -> 104.75301 | R33: =N33/$N$5*100 -> 90.852477 | AA33: 45078 | AB33: 4.1 | AE33: 43435 | AF33: 1.5 | AG33: 2.431 | AI33: 43466 | AJ33: 2.4 | AK33: 269.93 | AN33: 42979 | AO33: 5.5
L34: 45323 | M34: 7698.7 | N34: 0.6495 | P34: 45323 | Q34: =M34/$M$5*100 -> 104.9985 | R34: =N34/$N$5*100 -> 89.883753 | AA34: 45047 | AB34: 3.85 | AE34: 43466 | AF34: 1.5 | AG34: 2.271 | AI34: 43497 | AJ34: 2.4 | AK34: 278.68 | AN34: 43009 | AO34: 5.5
L35: 45352 | M35: 7896.9 | N35: 0.6521 | P35: 45352 | Q35: =M35/$M$5*100 -> 107.70164 | R35: =N35/$N$5*100 -> 90.243565 | AA35: 45017 | AB35: 3.6 | AE35: 43497 | AF35: 1.5 | AG35: 2.126 | AI35: 43525 | AJ35: 2.41 | AK35: 282.48 | AN35: 43040 | AO35: 5.5
L36: 45384 | M36: 7664.1 | N36: 0.6472 | P36: 45384 | Q36: =M36/$M$5*100 -> 104.52661 | R36: =N36/$N$5*100 -> 89.565458 | AA36: 44986 | AB36: 3.6 | AE36: 43525 | AF36: 1.5 | AG36: 1.957 | AI36: 43556 | AJ36: 2.42 | AK36: 294.02 | AN36: 43070 | AO36: 5.5
L37: 45413 | M37: 7701.7 | N37: 0.6652 | P37: 45413 | Q37: =M37/$M$5*100 -> 105.03942 | R37: =N37/$N$5*100 -> 92.056463 | AA37: 44958 | AB37: 3.35 | AE37: 43556 | AF37: 1.5 | AG37: 1.865 | AI37: 43586 | AJ37: 2.39 | AK37: 275.27 | AN37: 43101 | AO37: 5.6
L38: 45446 | M38: 7767.5 | N38: 0.6667 | P38: 45446 | Q38: =M38/$M$5*100 -> 105.93683 | R38: =N38/$N$5*100 -> 92.264046 | AA38: 44896 | AB38: 3.1 | AE38: 43586 | AF38: 1.5 | AG38: 1.655 | AI38: 43617 | AJ38: 2.38 | AK38: 293 | AN38: 43132 | AO38: 5.6
... L65: 46266 | M65: 9005.9 | N65: 0.7207 | P65: 46266 | Q65: =M65/$M$5*100 -> 122.82671 | R65: =N65/$N$5*100 -> 99.737061 | AA65: 44013 | AB65: 0.25 | AE65: 44409 | AF65: 0.1 | AG65: 1.135 | AI65: 44440 | AJ65: 0.08 | AK65: 429.14 | AN65: 43952 | AO65: 7.3
N66: 0.7315 | AA66: 43983 | AB66: 0.25 | AE66: 44440 | AF66: 0.1 | AG66: 1.282 | AI66: 44470 | AJ66: 0.08 | AK66: 459.25 | AN66: 43983 | AO66: 7.4
AA67: 43952 | AB67: 0.25 | AE67: 44470 | AF67: 0.1 | AG67: 1.71 | AI67: 44501 | AJ67: 0.08 | AK67: 455.56 | AN67: 44013 | AO67: 7.5
...

Sheet US
A1: Oil Prices | B1: LSEG 7/9 | N1: US CPI | O1: LSEG7/9 | AD1: Federal funds effective rate | AH1: S&P 500 index - LSEG 7/9 | AL1: LSEG | AP1: LSEG
B2: WTC- (MID_PRICE) | C2: .DXY (TRDPRC_1) | F2: LSEG | G2: LSEG | N2: fred.stlouisfed.org/series/CPIAUCSL | O2: fred.stlouisfed.org/graph/?g=rocU | V2: https://fred.stlouisfed.org/series/dgs10 , 7/9/26 | AD2: https://fred.stlouisfed.org/series/fedfunds | AE2: 46272
P3: USGDPA=ECI (ECONOMIC) | V3: Date | W3: US 10 yr treasury yield - | AD3: observation_date | AE3: FEDFUNDS | AH3: Date | AI3: SPY (TRDPRC_1) | AK3: Date | AL3: Fed Funds Rate (%) | AM3: SPY Close ($) | AN3: SPY YoY Return (%) | AP3: Date | AQ3: Fed Funds Rate (%) RHS | AR3: SPY Close ($) LHS
A4: Date | B4: WTC Oil Price | C4: USD Index | E4: Date | F4: WTC Oil Price | G4: USD Index | N4: Date | O4: CPI YoY Inflation (%) | P4: Real GDP Growth, Annualized (%) | V4: 42619 | W4: 1.55 | AD4: 42583 | AE4: 0.4 | AI4: Close | AK4: 42614 | AL4: 0.4 | AM4: 216.3 | AP4: 42979 | AQ4: 1.15 | AR4: 16.148867
A5: 44440 | B5: 75.22 | C5: 94.23 | E5: 44440 | F5: =B5/$B$5*100 -> 100 | G5: =C5/$B$5*100 -> 125.27253 | N5: 44470 | O5: 6.24 | P5: 6.5 | V5: 42620 | W5: 1.54 | AD5: 42614 | AE5: 0.4 | AH5: 46266 | AI5: 770.19 | AK5: 42644 | AL5: 0.4 | AM5: 212.55 | AP5: 43009 | AQ5: 1.15 | AR5: 20.983298
A6: 44470 | B6: 83.5 | C6: 94.123 | E6: 44470 | F6: =B6/$B$5*100 -> 111.00771 | G6: =C6/$B$5*100 -> 125.13028 | N6: 44562 | O6: 7.56 | P6: 2 | V6: 42621 | W6: 1.61 | AD6: 42644 | AE6: 0.4 | AH6: 46237 | AI6: 767.05 | AK6: 42675 | AL6: 0.41 | AM6: 220.38 | AP6: 43040 | AQ6: 1.16 | AR6: 20.251384
A7: 44501 | B7: 66.14 | C7: 95.994 | E7: 44501 | F7: =B7/$B$5*100 -> 87.928742 | G7: =C7/$B$5*100 -> 127.61765 | N7: 44652 | O7: 8.23 | P7: 6.9 | V7: 42622 | W7: 1.67 | AD7: 42675 | AE7: 0.41 | AH7: 46204 | AI7: 747.03 | AK7: 42705 | AL7: 0.54 | AM7: 223.53 | AP7: 43070 | AQ7: 1.3 | AR7: 19.384423
A8: 44531 | B8: 75.33 | C8: 95.968 | E8: 44531 | F8: =B8/$B$5*100 -> 100.14624 | G8: =C8/$B$5*100 -> 127.58309 | N8: 44743 | O8: 8.46 | P8: -1.4 | V8: 42625 | W8: 1.68 | AD8: 42705 | AE8: 0.54 | AH8: 46174 | AI8: 746.77 | AK8: 42736 | AL8: 0.65 | AM8: 227.53 | AP8: 43101 | AQ8: 1.41 | AR8: 23.89575
A9: 44564 | B9: 89.16 | C9: 96.54 | E9: 44564 | F9: =B9/$B$5*100 -> 118.53231 | G9: =C9/$B$5*100 -> 128.34353 | N9: 44835 | O9: 7.76 | P9: -0.9 | V9: 42626 | W9: 1.73 | AD9: 42736 | AE9: 0.65 | AH9: 46143 | AI9: 756.48 | AK9: 42767 | AL9: 0.66 | AM9: 236.47 | AP9: 43132 | AQ9: 1.42 | AR9: 14.877151
A10: 44593 | B10: 96.13 | C10: 96.707 | E10: 44593 | F10: =B10/$B$5*100 -> 127.79846 | G10: =C10/$B$5*100 -> 128.56554 | N10: 44927 | O10: 6.33 | P10: 2.6 | V10: 42627 | W10: 1.7 | AD10: 42767 | AE10: 0.66 | AH10: 46113 | AI10: 718.66 | AK10: 42795 | AL10: 0.79 | AM10: 235.74 | AP10: 43160 | AQ10: 1.51 | AR10: 11.627216
A11: 44621 | B11: 100.53 | C11: 98.312 | E11: 44621 | F11: =B11/$B$5*100 -> 133.64797 | G11: =C11/$B$5*100 -> 130.69928 | N11: 45017 | O11: 4.95 | P11: 2.9 | V11: 42628 | W11: 1.71 | AD11: 42795 | AE11: 0.79 | AH11: 46083 | AI11: 650.34 | AK11: 42826 | AL11: 0.9 | AM11: 238.08 | AP11: 43191 | AQ11: 1.69 | AR11: 11.10131
A12: 44652 | B12: 104.59 | C12: 102.959 | E12: 44652 | F12: =B12/$B$5*100 -> 139.04547 | G12: =C12/$B$5*100 -> 136.87716 | N12: 45108 | O12: 3.29 | P12: 1.1 | V12: 42629 | W12: 1.7 | AD12: 42826 | AE12: 0.9 | AH12: 46055 | AI12: 685.99 | AK12: 42856 | AL12: 0.91 | AM12: 241.44 | AP12: 43221 | AQ12: 1.7 | AR12: 12.218357
A13: 44683 | B13: 114.38 | C13: 101.752 | E13: 44683 | F13: =B13/$B$5*100 -> 152.06062 | G13: =C13/$B$5*100 -> 135.27253 | N13: 45200 | O13: 3.25 | P13: 2.4 | V13: 42632 | W13: 1.7 | AD13: 42856 | AE13: 0.91 | AH13: 46023 | AI13: 691.97 | AK13: 42887 | AL13: 1.04 | AM13: 241.8 | AP13: 43252 | AQ13: 1.82 | AR13: 12.191894
A14: 44713 | B14: 107.76 | C14: 104.685 | E14: 44713 | F14: =B14/$B$5*100 -> 143.25977 | G14: =C14/$B$5*100 -> 139.17176 | N14: 45292 | O14: 3.09 | P14: 4.9 | V14: 42633 | W14: 1.69 | AD14: 42887 | AE14: 1.04 | AH14: 45992 | AI14: 681.92 | AK14: 42917 | AL14: 1.15 | AM14: 246.77 | AP14: 43282 | AQ14: 1.91 | AR14: 14.004944
A15: 44743 | B15: 101.31 | C15: 105.903 | E15: 44743 | F15: =B15/$B$5*100 -> 134.68492 | G15: =C15/$B$5*100 -> 140.79101 | N15: 45383 | O15: 3.36 | P15: 3.3 | V15: 42634 | W15: 1.66 | AD15: 42917 | AE15: 1.15 | AH15: 45964 | AI15: 683.39 | AK15: 42948 | AL15: 1.16 | AM15: 247.49 | AP15: 43313 | AQ15: 1.91 | AR15: 17.301709
A16: 44774 | B16: 90.09 | C16: 108.7 | E16: 44774 | F16: =B16/$B$5*100 -> 119.76868 | G16: =C16/$B$5*100 -> 144.50944 | N16: 45474 | O16: 2.94 | P16: 1.6 | V16: 42635 | W16: 1.63 | AD16: 42948 | AE16: 1.16 | AH16: 45931 | AI16: 682.06 | AK16: 42979 | AL16: 1.15 | AM16: 251.23 | AN16: =(AM16/AM4-1)*100 -> 16.148867 | AP16: 43344 | AQ16: 1.95 | AR16: 15.718664
A17: 44805 | B17: 79.91 | C17: 112.117 | E17: 44805 | F17: =B17/$B$5*100 -> 106.23504 | G17: =C17/$B$5*100 -> 149.05211 | N17: 45566 | O17: 2.58 | P17: 2.8 | V17: 42636 | W17: 1.62 | AD17: 42979 | AE17: 1.15 | AH17: 45901 | AI17: 666.18 | AK17: 43009 | AL17: 1.15 | AM17: 257.15 | AN17: =(AM17/AM5-1)*100 -> 20.983298 | AP17: 43374 | AQ17: 2.19 | AR17: 5.2420766
A18: 44837 | B18: 86.54 | C18: 111.527 | E18: 44837 | F18: =B18/$B$5*100 -> 115.04919 | G18: =C18/$B$5*100 -> 148.26775 | N18: 45658 | O18: 2.99 | P18: 2.8 | V18: 42639 | W18: 1.59 | AD18: 43009 | AE18: 1.15 | AH18: 45870 | AI18: 645.05 | AK18: 43040 | AL18: 1.16 | AM18: 265.01 | AN18: =(AM18/AM6-1)*100 -> 20.251384 | AP18: 43405 | AQ18: 2.2 | AR18: 4.0149428
A19: 44866 | B19: 80.48 | C19: 105.95 | E19: 44866 | F19: =B19/$B$5*100 -> 106.99282 | G19: =C19/$B$5*100 -> 140.8535 | N19: 45748 | O19: 2.33 | P19: 2.3 | V19: 42640 | W19: 1.56 | AD19: 43040 | AE19: 1.16 | AH19: 45839 | AI19: 632.08 | AK19: 43070 | AL19: 1.3 | AM19: 266.86 | AN19: =(AM19/AM7-1)*100 -> 19.384423 | AP19: 43435 | AQ19: 2.27 | AR19: -6.3478978
A20: 44896 | B20: 80.16 | C20: 103.522 | E20: 44896 | F20: =B20/$B$5*100 -> 106.5674 | G20: =C20/$B$5*100 -> 137.62563 | N20: 45839 | O20: 2.74 | P20: -0.3 | V20: 42641 | W20: 1.57 | AD20: 43070 | AE20: 1.3 | AH20: 45810 | AI20: 617.85 | AK20: 43101 | AL20: 1.41 | AM20: 281.9 | AN20: =(AM20/AM8-1)*100 -> 23.89575 | AP20: 43466 | AQ20: 2.4 | AR20: -4.2461866
A21: 44929 | B21: 78.95 | C21: 102.097 | E21: 44929 | F21: =B21/$B$5*100 -> 104.95879 | G21: =C21/$B$5*100 -> 135.73119 | N21: 45931 | O21: 2.86 | P21: 3 | V21: 42642 | W21: 1.56 | AD21: 43101 | AE21: 1.41 | AH21: 45778 | AI21: 589.39 | AK21: 43132 | AL21: 1.42 | AM21: 271.65 | AN21: =(AM21/AM9-1)*100 -> 14.877151 | AP21: 43497 | AQ21: 2.4 | AR21: 2.5878888
A22: 44958 | B22: 76.88 | C22: 104.869 | E22: 44958 | F22: =B22/$B$5*100 -> 102.20686 | G22: =C22/$B$5*100 -> 139.41638 | N22: 46023 | O22: 2.39 | P22: 4.3 | V22: 42643 | W22: 1.6 | AD22: 43132 | AE22: 1.42 | AH22: 45748 | AI22: 554.54 | AK22: 43160 | AL22: 1.51 | AM22: 263.15 | AN22: =(AM22/AM10-1)*100 -> 11.627216 | AP22: 43525 | AQ22: 2.41 | AR22: 7.3456204
A23: 44986 | B23: 75.68 | C23: 102.506 | E23: 44986 | F23: =B23/$B$5*100 -> 100.61154 | G23: =C23/$B$5*100 -> 136.27493 | N23: 46113 | O23: 3.78 | P23: 1.4 | V23: 42646 | W23: 1.63 | AD23: 43160 | AE23: 1.51 | AH23: 45719 | AI23: 559.39 | AK23: 43191 | AL23: 1.69 | AM23: 264.51 | AN23: =(AM23/AM11-1)*100 -> 11.10131 | AP23: 43556 | AQ23: 2.42 | AR23: 11.156478
A24: 45019 | B24: 76.78 | C24: 101.659 | E24: 45019 | F24: =B24/$B$5*100 -> 102.07392 | G24: =C24/$B$5*100 -> 135.1489 | N24: 46204 | O24: 3.3 | P24: 2 | V24: 42647 | W24: 1.69 | AD24: 43191 | AE24: 1.69 | AH24: 45691 | AI24: 594.18 | AK24: 43221 | AL24: 1.7 | AM24: 270.94 | AN24: =(AM24/AM12-1)*100 -> 12.218357 | AP24: 43586 | AQ24: 2.39 | AR24: 1.5981398
A25: 45047 | B25: 68.11 | C25: 104.326 | E25: 45047 | F25: =B25/$B$5*100 -> 90.547727 | G25: =C25/$B$5*100 -> 138.6945 | V25: 42648 | W25: 1.72 | AD25: 43221 | AE25: 1.7 | AH25: 45658 | AI25: 601.82 | AK25: 43252 | AL25: 1.82 | AM25: 271.28 | AN25: =(AM25/AM13-1)*100 -> 12.191894 | AP25: 43617 | AQ25: 2.38 | AR25: 8.0064878
A26: 45078 | B26: 70.66 | C26: 102.912 | E26: 45078 | F26: =B26/$B$5*100 -> 93.937783 | G26: =C26/$B$5*100 -> 136.81468 | V26: 42649 | W26: 1.75 | AD26: 43252 | AE26: 1.82 | AH26: 45628 | AI26: 586.08 | AK26: 43282 | AL26: 1.91 | AM26: 281.33 | AN26: =(AM26/AM14-1)*100 -> 14.004944 | AP26: 43647 | AQ26: 2.4 | AR26: 5.7228166
A27: 45110 | B27: 81.8 | C27: 101.855 | E27: 45110 | F27: =B27/$B$5*100 -> 108.74767 | G27: =C27/$B$5*100 -> 135.40947 | V27: 42650 | W27: 1.73 | AD27: 43282 | AE27: 1.91 | AH27: 45597 | AI27: 602.55 | AK27: 43313 | AL27: 1.91 | AM27: 290.31 | AN27: =(AM27/AM15-1)*100 -> 17.301709 | AP27: 43678 | AQ27: 2.13 | AR27: 0.73714305
A28: 45139 | B28: 83.55 | C28: 103.619 | E28: 45139 | F28: =B28/$B$5*100 -> 111.07418 | G28: =C28/$B$5*100 -> 137.75459 | V28: 42653 | AD28: 43313 | AE28: 1.91 | AH28: 45566 | AI28: 568.64 | AK28: 43344 | AL28: 1.95 | AM28: 290.72 | AN28: =(AM28/AM16-1)*100 -> 15.718664 | AP28: 43709 | AQ28: 2.04 | AR28: 2.0810402
A29: 45170 | B29: 90.77 | C29: 106.224 | E29: 45170 | F29: =B29/$B$5*100 -> 120.67269 | G29: =C29/$B$5*100 -> 141.21776 | V29: 42654 | W29: 1.77 | AD29: 43344 | AE29: 1.95 | AH29: 45537 | AI29: 573.76 | AK29: 43374 | AL29: 2.19 | AM29: 270.63 | AN29: =(AM29/AM17-1)*100 -> 5.2420766 | AP29: 43739 | AQ29: 1.83 | AR29: 12.082918
A30: 45201 | B30: 81.64 | C30: 106.663 | E30: 45201 | F30: =B30/$B$5*100 -> 108.53496 | G30: =C30/$B$5*100 -> 141.80138 | V30: 42655 | W30: 1.79 | AD30: 43374 | AE30: 2.19 | AH30: 45505 | AI30: 563.68 | AK30: 43405 | AL30: 2.2 | AM30: 275.65 | AN30: =(AM30/AM18-1)*100 -> 4.0149428 | AP30: 43770 | AQ30: 1.55 | AR30: 14.025032
A31: 45231 | B31: 75.66 | C31: 103.497 | E31: 45231 | F31: =B31/$B$5*100 -> 100.58495 | G31: =C31/$B$5*100 -> 137.5924 | V31: 42656 | W31: 1.75 | AD31: 43405 | AE31: 2.2 | AH31: 45474 | AI31: 550.81 | AK31: 43435 | AL31: 2.27 | AM31: 249.92 | AN31: =(AM31/AM19-1)*100 -> -6.3478978 | AP31: 43800 | AQ31: 1.55 | AR31: 28.785211
A32: 45261 | B32: 71.89 | C32: 101.333 | E32: 45261 | F32: =B32/$B$5*100 -> 95.572986 | G32: =C32/$B$5*100 -> 134.7155 | V32: 42657 | W32: 1.8 | AD32: 43435 | AE32: 2.27 | AH32: 45446 | AI32: 544.22 | AK32: 43466 | AL32: 2.4 | AM32: 269.93 | AN32: =(AM32/AM20-1)*100 -> -4.2461866 | AP32: 43831 | AQ32: 1.55 | AR32: 19.19016
A33: 45293 | B33: 76.28 | C33: 103.274 | E33: 45293 | F33: =B33/$B$5*100 -> 101.4092 | G33: =C33/$B$5*100 -> 137.29593 | V33: 42660 | W33: 1.77 | AD33: 43466 | AE33: 2.4 | AH33: 45413 | AI33: 527.37 | AK33: 43497 | AL33: 2.4 | AM33: 278.68 | AN33: =(AM33/AM21-1)*100 -> 2.5878888 | AP33: 43862 | AQ33: 1.58 | AR33: 6.3083106
A34: 45323 | B34: 79.22 | C34: 104.156 | E34: 45323 | F34: =B34/$B$5*100 -> 105.31773 | G34: =C34/$B$5*100 -> 138.46849 | V34: 42661 | W34: 1.75 | AD34: 43497 | AE34: 2.4 | AH34: 45383 | AI34: 501.98 | AK34: 43525 | AL34: 2.41 | AM34: 282.48 | AN34: =(AM34/AM22-1)*100 -> 7.3456204 | AP34: 43891 | AQ34: 0.65 | AR34: -8.7546021
A35: 45352 | B35: 83.96 | C35: 104.546 | E35: 45352 | F35: =B35/$B$5*100 -> 111.61925 | G35: =C35/$B$5*100 -> 138.98697 | V35: 42662 | W35: 1.76 | AD35: 43525 | AE35: 2.41 | AH35: 45352 | AI35: 523.07 | AK35: 43556 | AL35: 2.42 | AM35: 294.02 | AN35: =(AM35/AM23-1)*100 -> 11.156478 | AP35: 43922 | AQ35: 0.05 | AR35: -1.2039997
A36: 45383 | B36: 83.49 | C36: 106.221 | E36: 45383 | F36: =B36/$B$5*100 -> 110.99442 | G36: =C36/$B$5*100 -> 141.21377 | V36: 42663 | W36: 1.76 | AD36: 43556 | AE36: 2.42 | AH36: 45323 | AI36: 508.08 | AK36: 43586 | AL36: 2.39 | AM36: 275.27 | AN36: =(AM36/AM24-1)*100 -> 1.5981398 | AP36: 43952 | AQ36: 0.05 | AR36: 10.553275
A37: 45413 | B37: 77.97 | C37: 104.671 | E37: 45413 | F37: =B37/$B$5*100 -> 103.65594 | G37: =C37/$B$5*100 -> 139.15315 | V37: 42664 | W37: 1.74 | AD37: 43586 | AE37: 2.39 | AH37: 45292 | AI37: 482.88 | AK37: 43617 | AL37: 2.38 | AM37: 293 | AN37: =(AM37/AM25-1)*100 -> 8.0064878 | AP37: 43983 | AQ37: 0.08 | AR37: 5.2423208
A38: 45446 | B38: 82.83 | C38: 105.866 | E38: 45446 | F38: =B38/$B$5*100 -> 110.11699 | G38: =C38/$B$5*100 -> 140.74182 | V38: 42667 | W38: 1.77 | AD38: 43617 | AE38: 2.38 | AH38: 45261 | AI38: 475.31 | AK38: 43647 | AL38: 2.4 | AM38: 297.43 | AN38: =(AM38/AM26-1)*100 -> 5.7228166 | AP38: 44013 | AQ38: 0.09 | AR38: 9.7804525
A39: 45474 | B39: 79.36 | C39: 104.096 | E39: 45474 | F39: =B39/$B$5*100 -> 105.50386 | G39: =C39/$B$5*100 -> 138.38873 | V39: 42668 | W39: 1.77 | AD39: 43647 | AE39: 2.4 | AH39: 45231 | AI39: 456.4 | AK39: 43678 | AL39: 2.13 | AM39: 292.45 | AN39: =(AM39/AM27-1)*100 -> 0.73714305 | AP39: 44044 | AQ39: 0.1 | AR39: 19.44264
A40: 45505 | B40: 74.52 | C40: 101.698 | E40: 45505 | F40: =B40/$B$5*100 -> 99.069396 | G40: =C40/$B$5*100 -> 135.20074 | V40: 42669 | W40: 1.79 | AD40: 43678 | AE40: 2.13 | AH40: 45201 | AI40: 418.2 | AK40: 43709 | AL40: 2.04 | AM40: 296.77 | AN40: =(AM40/AM28-1)*100 -> 2.0810402 | AP40: 44075 | AQ40: 0.09 | AR40: 12.844964
...

Sheet Euro
A1: Euro 10 yr GDP - LSEG 7/9 | E1: EURO STOXX 50 indexed performance - LSEG 7/9 | O1: data columns Q-V sourced from LSEG | P1: Date | Q1: STOXX 50 | R1: Oil & Gas Index | S1: EUR/USD | T1: STOXX 50 (Indexed) | U1: Oil & Gas Index (Indexed) | V1: EUR/USD (Indexed) | AI1: fred.stlouisfed.org/series/ECBDFR
E2: Euro oil and gas index | P2: 42552 | Q2: 3002.24 | R2: 279.53 | S2: 1.1238 | T2: =Q2/$Q$2*100 -> 100 | U2: =R2/$R$2*100 -> 100 | V2: =S2/$S$2*100 -> 100 | AI2: fred.stlouisfed.org/series/IRLTLT01DEM156N
A3: Date | B3: Euro Area Real GDP YoY (%) | C3: Euro Area HICP Inflation YoY (%) | F3: .STOXX50E (TRDPRC_1) | G3: .SXEE (TRDPRC_1) | I3: LSEG 7/9 | P3: 42644 | Q3: 3290.52 | R3: 324.01 | S3: 1.0513 | T3: =Q3/$Q$2*100 -> 109.60216 | U3: =R3/$R$2*100 -> 115.91242 | V3: =S3/$S$2*100 -> 93.548674
A4: 42552 | B4: 1.6 | C4: 0.27 | E4: Date | F4: STOXX 50 | G4: Oil & Gas Index | I4: Date | J4: EUR= (BID) | P4: 42736 | Q4: 3500.93 | R4: 319.2 | S4: 1.0649 | T4: =Q4/$Q$2*100 -> 116.6106 | U4: =R4/$R$2*100 -> 114.19168 | V4: =S4/$S$2*100 -> 94.758854 | AI4: Date | AJ4: ECB Deposit Facility Rate (%) | AK4: German 10Y Bund Yield (%)
A5: 42644 | B5: 1.8 | C5: 0.73 | E5: 46029 | F5: 6392.93 | G5: 591.56 | I5: Date | J5: Euro/USD | P5: 42826 | Q5: 3441.88 | R5: 288.48 | S5: 1.1423 | T5: =Q5/$Q$2*100 -> 114.64373 | U5: =R5/$R$2*100 -> 103.2018 | V5: =S5/$S$2*100 -> 101.6462 | AI5: 42614 | AJ5: -0.4 | AK5: -0.084090909
A6: 42736 | B6: 1.7 | C6: 1.73 | E6: 46026 | F6: 6328.09 | G6: 570.12 | I6: 46029 | J6: 1.1609 | P6: 42917 | Q6: 3594.85 | R6: 304.08 | S6: 1.1812 | T6: =Q6/$Q$2*100 -> 119.73893 | U6: =R6/$R$2*100 -> 108.7826 | V6: =S6/$S$2*100 -> 105.10767 | AI6: 42644 | AJ6: -0.4 | AK6: 0.002
A7: 42826 | B7: 2.1 | C7: 1.53 | E7: 46054 | F7: 5569.73 | G7: 603.75 | I7: 46026 | J7: 1.1421 | P7: 43009 | Q7: 3503.96 | R7: 309.81 | S7: 1.1996 | T7: =Q7/$Q$2*100 -> 116.71152 | U7: =R7/$R$2*100 -> 110.83247 | V7: =S7/$S$2*100 -> 106.74497 | AI7: 42675 | AJ7: -0.4 | AK7: 0.18909091
A8: 42917 | B8: 2.8 | C8: 1.47 | E8: 45667 | F8: 5791.41 | G8: 440.17 | I8: 46023 | J8: 1.1552 | P8: 43101 | Q8: 3361.5 | R8: 308.83 | S8: 1.2321 | T8: =Q8/$Q$2*100 -> 111.9664 | U8: =R8/$R$2*100 -> 110.48188 | V8: =S8/$S$2*100 -> 109.63695 | AI8: 42705 | AJ8: -0.4 | AK8: 0.25190476
A9: 43009 | B9: 2.8 | C9: 1.4 | E9: 45664 | F9: 5529.96 | G9: 399.94 | I9: 45667 | J9: 1.1745 | P9: 43191 | Q9: 3395.6 | R9: 347.47 | S9: 1.1683 | T9: =Q9/$Q$2*100 -> 113.10222 | U9: =R9/$R$2*100 -> 124.30508 | V9: =S9/$S$2*100 -> 103.95978 | AI9: 42736 | AJ9: -0.4 | AK9: 0.25090909
A10: 43101 | B10: 2.5 | C10: 1.27 | E10: 45661 | F10: 5303.24 | G10: 389.92 | I10: 45664 | J10: 1.1733 | P10: 43282 | Q10: 3399.2 | R10: 364.97 | S10: 1.1608 | T10: =Q10/$Q$2*100 -> 113.22213 | U10: =R10/$R$2*100 -> 130.56559 | V10: =S10/$S$2*100 -> 103.2924 | AI10: 42767 | AJ10: -0.4 | AK10: 0.258
A11: 43191 | B11: 2.2 | C11: 1.73 | E11: 45689 | F11: 5248.39 | G11: 369.41 | I11: 45661 | J11: 1.1786 | P11: 43374 | Q11: 3001.42 | R11: 302.78 | S11: 1.1469 | T11: =Q11/$Q$2*100 -> 99.972687 | U11: =R11/$R$2*100 -> 108.31753 | V11: =S11/$S$2*100 -> 102.05553 | AI11: 42795 | AJ11: -0.4 | AK11: 0.34826087
A12: 43282 | B12: 1.7 | C12: 2.13 | E12: 45301 | F12: 4895.98 | G12: 339.28 | I12: 45658 | J12: 1.0817 | P12: 43466 | Q12: 3351.71 | R12: 339.1 | S12: 1.1217 | T12: =Q12/$Q$2*100 -> 111.64031 | U12: =R12/$R$2*100 -> 121.31077 | V12: =S12/$S$2*100 -> 99.813134 | AI12: 42826 | AJ12: -0.4 | AK12: 0.22555556
A13: 43374 | B13: 1.2 | C13: 1.9 | E13: 45298 | F13: 5000.45 | G13: 342.89 | I13: 45301 | J13: 1.0353 | P13: 43556 | Q13: 3473.69 | R13: 329.1 | S13: 1.1368 | T13: =Q13/$Q$2*100 -> 115.70327 | U13: =R13/$R$2*100 -> 117.73334 | V13: =S13/$S$2*100 -> 101.15679 | AI13: 42856 | AJ13: -0.4 | AK13: 0.33636364
A14: 43466 | B14: 1.2 | C14: 1.43 | E14: 45326 | F14: 4894.02 | G14: 355.25 | I14: 45298 | J14: 1.1134 | P14: 43647 | Q14: 3569.45 | R14: 324.06 | S14: 1.0898 | T14: =Q14/$Q$2*100 -> 118.89289 | U14: =R14/$R$2*100 -> 115.93031 | V14: =S14/$S$2*100 -> 96.974551 | AI14: 42887 | AJ14: -0.4 | AK14: 0.25047619
A15: 43556 | B15: 1.1 | C15: 1.4 | E15: 45323 | F15: 5083.42 | G15: 361.78 | I15: 45295 | J15: 1.0713 | P15: 43739 | Q15: 3745.15 | R15: 328.43 | S15: 1.121 | T15: =Q15/$Q$2*100 -> 124.74519 | U15: =R15/$R$2*100 -> 117.49365 | V15: =S15/$S$2*100 -> 99.750845 | AI15: 42917 | AJ15: -0.4 | AK15: 0.45571429
A16: 43647 | B16: 1.1 | C16: 0.93 | E16: 44967 | F16: 4521.44 | G16: 350.16 | I16: 45292 | J16: 1.0793 | P16: 43831 | Q16: 2786.9 | R16: 228.81 | S16: 1.1029 | T16: =Q16/$Q$2*100 -> 92.827356 | U16: =R16/$R$2*100 -> 81.855257 | V16: =S16/$S$2*100 -> 98.140238 | AI16: 42948 | AJ16: -0.4 | AK16: 0.34608696
A17: 43739 | B17: 1 | C17: 1 | E17: 44992 | F17: 4174.66 | G17: 356.52 | I17: 44967 | J17: 1.1036 | P17: 43922 | Q17: 3234.07 | R17: 225.69 | S17: 1.1231 | T17: =Q17/$Q$2*100 -> 107.7219 | U17: =R17/$R$2*100 -> 80.739098 | V17: =S17/$S$2*100 -> 99.937711 | AI17: 42979 | AJ17: -0.4 | AK17: 0.34714286
... A42: 46023 | B42: 0.8 | C42: 2.07 | E42: 42798 | F42: 3441.88 | G42: 288.48 | I42: 42801 | J42: 1.1812 | P42: 46204 | Q42: 6392.93 | R42: 591.56 | S42: 1.1609 | T42: =Q42/$Q$2*100 -> 212.93867 | U42: =R42/$R$2*100 -> 211.62666 | V42: =S42/$S$2*100 -> 103.3013 | AI42: 43739 | AJ42: -0.5 | AK42: -0.46954545
A43: 46113 | B43: 1 | C43: 3 | E43: 42767 | F43: 3500.93 | G43: 319.2 | I43: 42798 | J43: 1.1423 | AI43: 43770 | AJ43: -0.5 | AK43: -0.35238095
E44: 42439 | F44: 3290.52 | G44: 324.01 | I44: 42767 | J44: 1.0649 | AI44: 43800 | AJ44: -0.5 | AK44: -0.29944444
E45: 42376 | F45: 3002.24 | G45: 279.53 | I45: 42439 | J45: 1.0513 | AI45: 43831 | AJ45: -0.5 | AK45: -0.31363636
I46: 42376 | J46: 1.1238 | AI46: 43862 | AJ46: -0.5 | AK46: -0.466
AI47: 43891 | AJ47: -0.5 | AK47: -0.54136364
AI48: 43922 | AJ48: -0.5 | AK48: -0.4495
AI49: 43952 | AJ49: -0.5 | AK49: -0.5165
AI50: 43983 | AJ50: -0.5 | AK50: -0.43428571
AI51: 44013 | AJ51: -0.5 | AK51: -0.52304348
AI52: 44044 | AJ52: -0.5 | AK52: -0.52333333
AI53: 44075 | AJ53: -0.5 | AK53: -0.52409091
AI54: 44105 | AJ54: -0.5 | AK54: -0.60727273
AI55: 44136 | AJ55: -0.5 | AK55: -0.6147619
AI56: 44166 | AJ56: -0.5 | AK56: -0.6185
AI57: 44197 | AJ57: -0.5 | AK57: -0.5835
AI58: 44228 | AJ58: -0.5 | AK58: -0.4455
... AI122: 46174 | AJ122: 2.25 | AK122: 2.97

Sheet Japan
A1: Japan 10 yr GDP - LSEG 7/9 | K1: Japan Interest Rates | R1: Japan Equities — Nikkei 225 & TOPIX, LSEG 7/9 | Y1: USD/JPY — LSEG 7/9
K2: 10Y JGB Yield: LSEG 7/9 | Short-Term Rate: FRED IRSTCI01JPM156N
B3: JPGD1=ECI (ECONOMIC) | C3: JPCPO=ECI (ECONOMIC) | L3: aJPGBOND (ECONOMIC) | M3: IRSTCI01JPM156N | Q3: .N225E (TRDPRC_1) | R3: .TOPX (TRDPRC_1) | Z3: JPY= (BID)
A4: Date | B4: Japan Real GDP Growth, QoQ (%) | C4: Japan CPI Inflation, YoY (%) | K4: Date | L4: Japan 10-Year JGB Yield (%) | M4: Japan Short-Term Interest Rate (%) | P4: Date | Q4: Nikkei 225 (Close) | R4: TOPIX (Close) | U4: Date | V4: Nikkei 225 | W4: TOPIX | Y4: Date | Z4: USD/JPY (Close)
A5: 42552 | B5: 0.5 | C5: -0.4 | K5: 42522 | L5: -0.07 | M5: -0.055 | P5: 42522 | Q5: 16449.84 | R5: 1322.78 | U5: 42522 | V5: =Q5/$Q$5*100 -> 100 | W5: =R5/$R$5*100 -> 100 | Y5: 42522 | Z5: 101.33
A6: 42644 | B6: 0.2 | C6: 0.1 | K6: 42552 | L6: -0.08 | M6: -0.043 | P6: 42552 | Q6: 17425.02 | R6: 1393.02 | U6: 42552 | V6: =Q6/$Q$5*100 -> 105.9282 | W6: =R6/$R$5*100 -> 105.31003 | Y6: 42552 | Z6: 104.81
A7: 42736 | B7: 0.5 | C7: 0.4 | K7: 42583 | L7: -0.05 | M7: -0.043 | P7: 42583 | Q7: 18308.48 | R7: 1469.43 | U7: 42583 | V7: =Q7/$Q$5*100 -> 111.29883 | W7: =R7/$R$5*100 -> 111.0865 | Y7: 42583 | Z7: 114.44
A8: 42826 | B8: 1 | C8: 0.4 | K8: 42614 | L8: 0.02 | M8: -0.052 | P8: 42614 | Q8: 19114.37 | R8: 1518.61 | U8: 42614 | V8: =Q8/$Q$5*100 -> 116.19791 | W8: =R8/$R$5*100 -> 114.80443 | Y8: 42614 | Z8: 116.87
A9: 42917 | B9: 0.3 | C9: 0.4 | K9: 42644 | L9: 0.05 | M9: -0.037 | P9: 42644 | Q9: 19041.34 | R9: 1521.67 | U9: 42644 | V9: =Q9/$Q$5*100 -> 115.75395 | W9: =R9/$R$5*100 -> 115.03576 | Y9: 42644 | Z9: 112.78
A10: 43009 | B10: 0.1 | C10: 0.2 | K10: 42675 | L10: 0.09 | M10: -0.049 | P10: 42675 | Q10: 19118.99 | R10: 1535.32 | U10: 42675 | V10: =Q10/$Q$5*100 -> 116.22599 | W10: =R10/$R$5*100 -> 116.06768 | Y10: 42675 | Z10: 112.75
A11: 43101 | B11: -0.2 | C11: 1.4 | K11: 42705 | L11: 0.05 | M11: -0.044 | P11: 42705 | Q11: 18909.26 | R11: 1512.6 | U11: 42705 | V11: =Q11/$Q$5*100 -> 114.95103 | W11: =R11/$R$5*100 -> 114.35008 | Y11: 42705 | Z11: 111.38
A12: 43191 | B12: 0.5 | C12: 0.6 | K12: 42736 | L12: 0.07 | M12: -0.045 | P12: 42736 | Q12: 19196.74 | R12: 1531.8 | U12: 42736 | V12: =Q12/$Q$5*100 -> 116.69864 | W12: =R12/$R$5*100 -> 115.80157 | Y12: 42736 | Z12: 111.53
A13: 43282 | B13: -0.3 | C13: 0.9 | K13: 42767 | L13: 0.02 | M13: -0.038 | P13: 42767 | Q13: 19650.57 | R13: 1568.37 | U13: 42767 | V13: =Q13/$Q$5*100 -> 119.45751 | W13: =R13/$R$5*100 -> 118.5662 | Y13: 42767 | Z13: 110.75
A14: 43374 | B14: 0.3 | C14: 1.4 | K14: 42795 | L14: 0.04 | M14: -0.042 | P14: 42795 | Q14: 20033.43 | R14: 1611.9 | U14: 42795 | V14: =Q14/$Q$5*100 -> 121.78495 | W14: =R14/$R$5*100 -> 121.857 | Y14: 42795 | Z14: 112.35
A15: 43466 | B15: 0.5 | C15: 0.2 | K15: 42826 | L15: 0.08 | M15: -0.054 | P15: 42826 | Q15: 19925.18 | R15: 1618.61 | U15: 42826 | V15: =Q15/$Q$5*100 -> 121.12689 | W15: =R15/$R$5*100 -> 122.36426 | Y15: 42826 | Z15: 110.25
A16: 43556 | B16: 0.4 | C16: 0.9 | K16: 42856 | L16: 0.08 | M16: -0.053 | P16: 42856 | Q16: 19646.24 | R16: 1617.41 | U16: 42856 | V16: =Q16/$Q$5*100 -> 119.43119 | W16: =R16/$R$5*100 -> 122.27355 | Y16: 42856 | Z16: 109.96
... A44: 46113 | B44: 0.3 | C44: 1.4 | K44: 43709 | L44: -0.08 | M44: -0.059 | P44: 43709 | Q44: 23656.62 | R44: 1721.36 | U44: 43709 | V44: =Q44/$Q$5*100 -> 143.81064 | W44: =R44/$R$5*100 -> 130.13199 | Y44: 43709 | Z44: 108.61
K45: 43739 | L45: -0.02 | M45: -0.021 | P45: 43739 | Q45: 23205.18 | R45: 1684.44 | U45: 43739 | V45: =Q45/$Q$5*100 -> 141.0663 | W45: =R45/$R$5*100 -> 127.3409 | Y45: 43739 | Z45: 108.38
K46: 43770 | L46: -0.06 | M46: -0.043 | P46: 43770 | Q46: 21142.96 | R46: 1510.87 | U46: 43770 | V46: =Q46/$Q$5*100 -> 128.52988 | W46: =R46/$R$5*100 -> 114.2193 | Y46: 43770 | Z46: 108.07
K47: 43800 | L47: -0.15 | M47: -0.038 | P47: 43800 | Q47: 18917.01 | R47: 1403.04 | U47: 43800 | V47: =Q47/$Q$5*100 -> 114.99814 | W47: =R47/$R$5*100 -> 106.06752 | Y47: 43800 | Z47: 107.53
K48: 43831 | L48: 0.02 | M48: -0.032 | P48: 43831 | Q48: 20193.69 | R48: 1464.03 | U48: 43831 | V48: =Q48/$Q$5*100 -> 122.75919 | W48: =R48/$R$5*100 -> 110.67827 | Y48: 43831 | Z48: 107.17
K49: 43862 | L49: -0.04 | M49: -0.016 | P49: 43862 | Q49: 21877.89 | R49: 1563.67 | U49: 43862 | V49: =Q49/$Q$5*100 -> 132.99759 | W49: =R49/$R$5*100 -> 118.21089 | Y49: 43862 | Z49: 107.77
K50: 43891 | L50: 0.01 | M50: -0.047 | P50: 43891 | Q50: 22288.14 | R50: 1558.77 | U50: 43891 | V50: =Q50/$Q$5*100 -> 135.49153 | W50: =R50/$R$5*100 -> 117.84046 | Y50: 43891 | Z50: 107.92
K51: 43922 | L51: 0.03 | M51: -0.036 | P51: 43922 | Q51: 21710 | R51: 1496.06 | U51: 43922 | V51: =Q51/$Q$5*100 -> 131.97697 | W51: =R51/$R$5*100 -> 113.09968 | Y51: 43922 | Z51: 105.88
K52: 43952 | L52: 0.02 | M52: -0.047 | P52: 43952 | Q52: 23139.76 | R52: 1618.18 | U52: 43952 | V52: =Q52/$Q$5*100 -> 140.6686 | W52: =R52/$R$5*100 -> 122.33176 | Y52: 43952 | Z52: 105.89
K53: 43983 | L53: 0.05 | M53: -0.048 | P53: 43983 | Q53: 23185.12 | R53: 1625.49 | U53: 43983 | V53: =Q53/$Q$5*100 -> 140.94435 | W53: =R53/$R$5*100 -> 122.88438 | Y53: 43983 | Z53: 105.45
K54: 44013 | L54: 0.02 | M54: -0.028 | P54: 44013 | Q54: 22977.13 | R54: 1579.33 | U54: 44013 | V54: =Q54/$Q$5*100 -> 139.67996 | W54: =R54/$R$5*100 -> 119.39476 | Y54: 44013 | Z54: 104.64
K55: 44044 | L55: 0.04 | M55: -0.035 | P55: 44044 | Q55: 26433.62 | R55: 1754.92 | U55: 44044 | V55: =Q55/$Q$5*100 -> 160.69226 | W55: =R55/$R$5*100 -> 132.66908 | Y55: 44044 | Z55: 104.27
K56: 44075 | L56: 0.03 | M56: -0.054 | P56: 44075 | Q56: 27444.17 | R56: 1804.68 | U56: 44075 | V56: =Q56/$Q$5*100 -> 166.83548 | W56: =R56/$R$5*100 -> 136.43085 | Y56: 44075 | Z56: 103.24
... K125: 46174 | L125: 2.94 | M125: 0.841 | P125: 46174 | Q125: 65020.94 | R125: 4118.11 | U125: 46174 | V125: =Q125/$Q$5*100 -> 395.26792 | W125: =R125/$R$5*100 -> 311.32237 | Y125: 46174 | Z125: 156.14

Sheet RF
A1: RF
A2: Daily 10y bond yields | D2: Each daily rate is expressed per year.
A4: Date | B4: % Rf year | C4: % Rf av year | D4: Rf (decimal) | F4: %Rf daily | G4: Rf daily (decimal)
A5: observation_date | B5: DGS10 | C5: =AVERAGEIFS(B6:B1310,A6:A1310,">="&Portfolio!BV12,A6:A1310,"<="&Portfolio!BV31) -> 3.777789 | D5: =C5/100 -> 0.03777789 | F5: =C5/252 -> 0.014991226 | G5: =F5/100 -> 0.00014991226
A6: 44461 | B6: 1.32
A7: 44462 | B7: 1.41
A8: 44463 | B8: 1.47
A9: 44466 | B9: 1.48
A10: 44467 | B10: 1.54
A11: 44468 | B11: 1.55
A12: 44469 | B12: 1.52
A13: 44470 | B13: 1.48
A14: 44473 | B14: 1.49
A15: 44474 | B15: 1.54
A16: 44475 | B16: 1.53
A17: 44476 | B17: 1.58
A18: 44477 | B18: 1.61
A19: 44480
A20: 44481 | B20: 1.59
A21: 44482 | B21: 1.56
A22: 44483 | B22: 1.52
A23: 44484 | B23: 1.59
A24: 44487 | B24: 1.59
A25: 44488 | B25: 1.65
A26: 44489 | B26: 1.65
A27: 44490 | B27: 1.68
A28: 44491 | B28: 1.66
A29: 44494 | B29: 1.64
A30: 44495 | B30: 1.63
A31: 44496 | B31: 1.54
... A41: 44510 | B41: 1.56
A42: 44511
A43: 44512 | B43: 1.58
A44: 44515 | B44: 1.63
A45: 44516 | B45: 1.63
A46: 44517 | B46: 1.6
A47: 44518 | B47: 1.59
A48: 44519 | B48: 1.54
A49: 44522 | B49: 1.63
A50: 44523 | B50: 1.67
...

Sheet Portfolio
B10: 60/40 | BV10: Quarterly Backtest (portfolio value, quarter to quarter)
B11: Ric | C11: Name | D11: Region | E11: Asset Class | F11: Type | G11: MER | H11: Return | I11: Return - MER | J11: Risk | K11: Drawdown | L11: Weight | M11: Total Risk | N11: Total Drawdown | O11: Total Return | BV11: Date | BW11: Aggressive | BX11: Strategic Backtest | BY11: Defensive | CA11: Column1 | CB11: 80/20 Tactical - Aggressive | CC11: 70/30 Strategic Backtest | CD11: 60/40 Tactical - Defensive
B12: BILL.AX | C12: iShares Core Cash ETF | D12: Australia | E12: Cash | F12: Defensive | G12: 0.0007 | H12: =T15 -> 0.00086268851 | I12: =H12-G12 -> 0.00016268851 | J12: =T16 -> 0.0014583498 | K12: =T18 -> -0.0015873016 | L12: 0.2 | M12: =J12*L12 -> 0.00029166995 | N12: =K12*L12 -> -0.00031746032 | O12: =I12*L12 -> 3.2537702e-05 | BV12: 44469 | CA12: Quarterly Mean | CB12: =AVERAGE(BW13:BW31) -> 0.022554304 | CC12: =AVERAGE(BX13:BX31) -> 0.02473175 | CD12: =AVERAGE(BY13:BY31) -> 0.024587001
B13: SPY.AX | C13: SPDR S&P 500 ETF Trust | D13: United States | E13: Equities | F13: Growth | G13: 0.0009 | H13: =X15 -> 0.12566444 | I13: =H13-G13 -> 0.12476444 | J13: =X16 -> 0.13229761 | K13: =X18 -> -0.16545205 | L13: 0.29 | M13: =J13*L13 -> 0.038366307 | N13: =K13*L13 -> -0.047981095 | O13: =I13*L13 -> 0.036181687 | R13: Monthly Mean | T13: =AVERAGE(S22:S83) -> 7.1890709e-05 | V13: Monthly Mean | X13: =AVERAGE(W22:W83) -> 0.010472037 | Z13: Monthly Mean | AB13: =AVERAGE(AA22:AA83) -> 0.0050774589 | AD13: Monthly Mean | AF13: =AVERAGE(AE22:AE83) -> 0.012974092 | AH13: Monthly Mean | AJ13: =AVERAGE(AI22:AI83) -> 0.015784585 | AL13: Monthly Mean | AN13: =AVERAGE(AM22:AM83) -> -0.0026154095 | AP13: Monthly Mean | AR13: =AVERAGE(AQ22:AQ83) -> 0.0038955483 | AT13: Monthly Mean | AV13: =AVERAGE(AU22:AU83) -> 4.9067197e-05 | AX13: Monthly Mean | AZ13: =AVERAGE(AY22:AY83) -> 0.0097028547 | BB13: Monthly Mean | BD13: =AVERAGE(BC22:BC83) -> 0.0033162475 | BF13: Monthly Mean | BH13: =AVERAGE(BG22:BG83) -> -0.00074885233 | BJ13: Monthly Mean | BL13: =AVERAGE(BK22:BK83) -> 0.0076708652 | BN13: Monthly Mean | BP13: =AVERAGE(BO22:BO83) -> 0.0076892299 | BR13: Monthly Mean | BT13: =AVERAGE(BS22:BS83) -> 0.0070080238 | BV13: 44561 | BW13: =BR27/BR24-1 -> 0.043367021 | BX13: =BN27/BN24-1 -> 0.042835458 | BY13: =BJ27/BJ24-1 -> 0.043336672 | CA13: Quarterly Std. Dev. | CB13: =STDEV(BW13:BW31) -> 0.050141395 | CC13: =STDEV(BX13:BX31) -> 0.050665528 | CD13: =STDEV(BY13:BY31) -> 0.042558185
B14: ESGI.AX | C14: VanEck MSCI International Sustainable Equity ETF | D14: Global | E14: Equities | F14: Growth | G14: 0.0055 | H14: =AB15 -> 0.060929507 | I14: =H14-G14 -> 0.055429507 | J14: =AB16 -> 0.12936696 | K14: =AB18 -> -0.20283323 | L14: 0.1544 | M14: =J14*L14 -> 0.019974259 | N14: =K14*L14 -> -0.03131745 | O14: =I14*L14 -> 0.0085583159 | R14: Monthly Std. Dev. | T14: =STDEV(S22:S83) -> 0.00042098931 | V14: Monthly Std. Dev. | X14: =STDEV(W22:W83) -> 0.03819103 | Z14: Monthly Std. Dev. | AB14: =STDEV(AA22:AA83) -> 0.037345025 | AD14: Monthly Std. Dev. | AF14: =STDEV(AE22:AE83) -> 0.049400651 | AH14: Monthly Std. Dev. | AJ14: =STDEV(AI22:AI83) -> 0.045561653 | AL14: Monthly Std. Dev. | AN14: =STDEV(AM22:AM83) -> 0.014913014 | AP14: Monthly Std. Dev. | AR14: =STDEV(AQ22:AQ83) -> 0.029509921 | AT14: Monthly Std. Dev. | AV14: =STDEV(AU22:AU83) -> 0.00031043957 | AX14: Monthly Std. Dev. | AZ14: =STDEV(AY22:AY83) -> 0.038613274 | BB14: Monthly Std. Dev. | BD14: =STDEV(BC22:BC83) -> 0.039333116 | BF14: Monthly Std. Dev. | BH14: =STDEV(BG22:BG83) -> 0.012067518 | BJ14: Monthly Std. Dev. | BL14: =STDEV(BK22:BK83) -> 0.02028696 | BN14: Monthly Std. Dev. | BP14: =STDEV(BO22:BO83) -> 0.023391403 | BR14: Monthly Std. Dev. | BT14: =STDEV(BS22:BS83) -> 0.024952481 | BV14: 44651 | BW14: =BR30/BR27-1 -> -0.039704137 | BX14: =BN30/BN27-1 -> -0.045421409 | BY14: =BJ30/BJ27-1 -> -0.037804718 | CA14: Mean Return (Annualised) | CB14: =CB12*4 -> 0.090217217 | CC14: =CC12*4 -> 0.098927002 | CD14: =CD12*4 -> 0.098348004
B15: HJPN.AX | C15: BetaShares Japan ETF (Currency Hedged) | D15: Japan | E15: Equities | F15: Growth | G15: 0.0056 | H15: =AF15 -> 0.1556891 | I15: =H15-G15 -> 0.1500891 | J15: =AF16 -> 0.17112888 | K15: =AF18 -> -0.21497585 | L15: 0.1 | M15: =J15*L15 -> 0.017112888 | N15: =K15*L15 -> -0.021497585 | O15: =I15*L15 -> 0.01500891 | R15: Mean Return (Annualised) | T15: =T13*12 -> 0.00086268851 | V15: Mean Return (Annualised) | X15: =X13*12 -> 0.12566444 | Z15: Mean Return (Annualised) | AB15: =AB13*12 -> 0.060929507 | AD15: Mean Return (Annualised) | AF15: =AF13*12 -> 0.1556891 | AH15: Mean Return (Annualised) | AJ15: =AJ13*12 -> 0.18941503 | AL15: Mean Return (Annualised) | AN15: =AN13*12 -> -0.031384914 | AP15: Mean Return (Annualised) | AR15: =AR13*12 -> 0.04674658 | AT15: Mean Return (Annualised) | AV15: =AV13*12 -> 0.00058880637 | AX15: Mean Return (Annualised) | AZ15: =AZ13*12 -> 0.11643426 | BB15: Mean Return (Annualised) | BD15: =BD13*12 -> 0.03979497 | BF15: Mean Return (Annualised) | BH15: =BH13*12 -> -0.0089862279 | BJ15: Mean Return (Annualised) | BL15: =BL13*12 -> 0.092050383 | BN15: Mean Return (Annualised) | BP15: =BP13*12 -> 0.092270759 | BR15: Mean Return (Annualised) | BT15: =BT13*12 -> 0.084096285 | BV15: 44742 | BW15: =BR33/BR30-1 -> -0.072070418 | BX15: =BN33/BN30-1 -> -0.057959021 | BY15: =BJ33/BJ30-1 -> -0.050118329 | CA15: Std. Dev. (Annualised) | CB15: =CB13*SQRT(4) -> 0.10028279 | CC15: =CC13*SQRT(4) -> 0.10133106 | CD15: =CD13*SQRT(4) -> 0.085116371
B16: GOLD.AX | C16: Global X Physical Gold | D16: Global | E16: Alternatives (Gold) | F16: Defensive | G16: 0.004 | H16: =AJ15 -> 0.18941503 | I16: =H16-G16 -> 0.18541503 | J16: =AJ16 -> 0.1578302 | K16: =AJ18 -> -0.22099853 | L16: 0.15 | M16: =J16*L16 -> 0.023674529 | N16: =K16*L16 -> -0.03314978 | O16: =I16*L16 -> 0.027812254 | R16: Std. Dev. (Annualised) | T16: =T14*SQRT(12) -> 0.0014583498 | V16: Std. Dev. (Annualised) | X16: =X14*SQRT(12) -> 0.13229761 | Z16: Std. Dev. (Annualised) | AB16: =AB14*SQRT(12) -> 0.12936696 | AD16: Std. Dev. (Annualised) | AF16: =AF14*SQRT(12) -> 0.17112888 | AH16: Std. Dev. (Annualised) | AJ16: =AJ14*SQRT(12) -> 0.1578302 | AL16: Std. Dev. (Annualised) | AN16: =AN14*SQRT(12) -> 0.051660197 | AP16: Std. Dev. (Annualised) | AR16: =AR14*SQRT(12) -> 0.10222536 | AT16: Std. Dev. (Annualised) | AV16: =AV14*SQRT(12) -> 0.0010753942 | AX16: Std. Dev. (Annualised) | AZ16: =AZ14*SQRT(12) -> 0.1337603 | BB16: Std. Dev. (Annualised) | BD16: =BD14*SQRT(12) -> 0.13625391 | BF16: Std. Dev. (Annualised) | BH16: =BH14*SQRT(12) -> 0.04180311 | BJ16: Std. Dev. (Annualised) | BL16: =BL14*SQRT(12) -> 0.070276091 | BN16: Std. Dev. (Annualised) | BP16: =BP14*SQRT(12) -> 0.081030196 | BR16: Std. Dev. (Annualised) | BT16: =BT14*SQRT(12) -> 0.08643793 | BV16: 44834 | BW16: =BR36/BR33-1 -> -0.021612661 | BX16: =BN36/BN33-1 -> -0.02394128 | BY16: =BJ36/BJ33-1 -> -0.018492085 | CA16: Sharpe Ratio | CB16: =(CB14-RF!$D$5)/CB15 -> 0.52291451 | CC16: =(CC14-RF!$D$5)/CC15 -> 0.60345875 | CD16: =(CD14-RF!$D$5)/CD15 -> 0.71161532
B17: VEFI.AX | C17: Vanguard Ethically Conscious Global Aggregate Bond Idx Hedged ETF | D17: Global | E17: Bonds | F17: Defensive | G17: 0.0026 | H17: =AN15 -> -0.031384914 | I17: =H17-G17 -> -0.033984914 | J17: =AN16 -> 0.051660197 | K17: =AN18 -> -0.19258517 | L17: 0.04 | M17: =J17*L17 -> 0.0020664079 | N17: =K17*L17 -> -0.0077034068 | O17: =I17*L17 -> -0.0013593966 | R17: Return-to-Variability Ratio | T17: =T15/T16 -> 0.59155117 | V17: Return-to-Variability Ratio | X17: =X15/X16 -> 0.94986174 | Z17: Return-to-Variability Ratio | AB17: =AB15/AB16 -> 0.47098197 | AD17: Return-to-Variability Ratio | AF17: =AF15/AF16 -> 0.90977691 | AH17: Return-to-Variability Ratio | AJ17: =AJ15/AJ16 -> 1.2001191 | AL17: Return-to-Variability Ratio | AN17: =AN15/AN16 -> -0.60752603 | AP17: Return-to-Variability Ratio | AR17: =AR15/AR16 -> 0.45728944 | AT17: Return-to-Variability Ratio | AV17: =AV15/AV16 -> 0.54752608 | AX17: Return-to-Variability Ratio | AZ17: =AZ15/AZ16 -> 0.87046944 | BB17: Return-to-Variability Ratio | BD17: =BD15/BD16 -> 0.29206479 | BF17: Return-to-Variability Ratio | BH17: =BH15/BH16 -> -0.21496553 | BJ17: Return-to-Variability Ratio | BL17: =BL15/BL16 -> 1.3098393 | BN17: Return-to-Variability Ratio | BP17: =BP15/BP16 -> 1.1387207 | BR17: Return-to-Variability Ratio | BT17: =BT15/BT16 -> 0.97290953 | BV17: 44925 | BW17: =BR39/BR36-1 -> 0.031804356 | BX17: =BN39/BN36-1 -> 0.038013866 | BY17: =BJ39/BJ36-1 -> 0.035109544 | CA17: Max Drawdown | CB17: =BT18 -> -0.12817182 | CC17: =BP18 -> -0.1222771 | CD17: =BL18 -> -0.10292958
B18: VBLD.AX | C18: Vanguard Global Infrastructure Index ETF | D18: Global | E18: Infrastructure | F18: Growth | G18: 0.0047 | H18: =AR15 -> 0.04674658 | I18: =H18-G18 -> 0.04204658 | J18: =AR16 -> 0.10222536 | K18: =AR18 -> -0.11622276 | L18: 0.0456 | M18: =J18*L18 -> 0.0046614766 | N18: =K18*L18 -> -0.0052997579 | O18: =I18*L18 -> 0.001917324 | R18: Max Drawdown | T18: =MIN(T22:T83) -> -0.0015873016 | V18: Max Drawdown | X18: =MIN(X22:X83) -> -0.16545205 | Z18: Max Drawdown | AB18: =MIN(AB22:AB83) -> -0.20283323 | AD18: Max Drawdown | AF18: =MIN(AF22:AF83) -> -0.21497585 | AH18: Max Drawdown | AJ18: =MIN(AJ22:AJ83) -> -0.22099853 | AL18: Max Drawdown | AN18: =MIN(AN22:AN83) -> -0.19258517 | AP18: Max Drawdown | AR18: =MIN(AR22:AR83) -> -0.11622276 | AT18: Max Drawdown | AV18: =MIN(AV22:AV83) -> -0.0013919268 | AX18: Max Drawdown | AZ18: =MIN(AZ22:AZ83) -> -0.18097976 | BB18: Max Drawdown | BD18: =MIN(BD22:BD83) -> -0.17873303 | BF18: Max Drawdown | BH18: =MIN(BH22:BH83) -> -0.11666045 | BJ18: Max Drawdown | BL18: =MIN(BL22:BL83) -> -0.10292958 | BN18: Max Drawdown | BP18: =MIN(BP22:BP83) -> -0.1222771 | BR18: Max Drawdown | BT18: =MIN(BT22:BT83) -> -0.12817182 | BV18: 45016 | BW18: =BR42/BR39-1 -> 0.047418801 | BX18: =BN42/BN39-1 -> 0.056052662 | BY18: =BJ42/BJ39-1 -> 0.053188093
B19: AAA.AX | C19: BetaShares Australian High Interest Cash ETF | D19: Australia | E19: Cash | F19: Defensive | G19: 0.0018 | H19: =AV15 -> 0.00058880637 | I19: =H19-G19 -> -0.0012111936 | J19: =AV16 -> 0.0010753942 | K19: =AV18 -> -0.0013919268 | L19: 0.01 | M19: =J19*L19 -> 1.0753942e-05 | N19: =K19*L19 -> -1.3919268e-05 | O19: =I19*L19 -> -1.2111936e-05 | BV19: 45107 | BW19: =BR45/BR42-1 -> 0.062920718 | BX19: =BN45/BN42-1 -> 0.06037837 | BY19: =BJ45/BJ42-1 -> 0.04640702
B20: VTS.AX | C20: Vanguard US Total Market Shares Index ETF | D20: United States | E20: Equities | F20: Growth | G20: 0.0003 | H20: =AZ15 -> 0.11643426 | I20: =H20-G20 -> 0.11613426 | J20: =AZ16 -> 0.1337603 | K20: =AZ18 -> -0.18097976 | L20: 0.01 | M20: =J20*L20 -> 0.001337603 | N20: =K20*L20 -> -0.0018097976 | O20: =I20*L20 -> 0.0011613426 | R20: iShares Core Cash ETF | V20: SPDR S&P 500 ETF Trust | Z20: VanEck MSCI International Sustainable Equity ETF | AD20: BetaShares Japan ETF (Currency Hedged) | AH20: Global X Physical Gold | AL20: Vanguard Ethically Conscious Global Aggregate Bond Idx Hedged ETF | AP20: Vanguard Global Infrastructure Index ETF | AT20: BetaShares Australian High Interest Cash ETF | AX20: Vanguard US Total Market Shares Index ETF | BB20: Vanguard Ethically Conscious Australian Shares ETF | BF20: Vanguard Australia Corporate Fixed Interest Index ETF | BJ20: Portfolio (60/40) | BN20: Portfolio (70/30) | BR20: Portfolio (80/20) | BV20: 45198 | BW20: =BR48/BR45-1 -> -0.018073652 | BX20: =BN48/BN45-1 -> -0.012251045 | BY20: =BJ48/BJ45-1 -> -0.010509204
L21: =SUM(L12:L20) -> 1 | M21: =SUM(M12:M20) -> 0.10749589 | N21: =SUM(N12:N20) -> -0.14909025 | O21: =SUM(O12:O20) -> 0.089300863 | Q21: Date | R21: BILL.AX | S21: Return (%) | T21: Drawdown | V21: SPY.AX | W21: Return (%) | X21: Drawdown | Z21: ESGI.AX | AA21: Return (%) | AB21: Drawdown | AD21: HJPN.AX | AE21: Return (%) | AF21: Drawdown | AH21: GOLD.AX | AI21: Return (%) | AJ21: Drawdown | AL21: VEFI.AX | AM21: Return (%) | AN21: Drawdown | AP21: VBLD.AX | AQ21: Return (%) | AR21: Drawdown | AT21: AAA.AX | AU21: Return (%) | AV21: Drawdown | AX21: VTS.AX | AY21: Return (%) | AZ21: Drawdown | BB21: VETH.AX | BC21: Return (%) | BD21: Drawdown | BF21: VACF.AX | BG21: Return (%) | BH21: Drawdown | BJ21: Value (100) | BK21: Return (%) | BL21: Drawdown | BN21: Value (100) | BO21: Return (%) | BP21: Drawdown | BR21: Value (100) | BS21: Return (%) | BT21: Drawdown | BV21: 45289 | BW21: =BR51/BR48-1 -> 0.044747265 | BX21: =BN51/BN48-1 -> 0.042906247 | BY21: =BJ51/BJ48-1 -> 0.04297003
L22: Actual portfolio | M22: =BL16 -> 0.070276091 | N22: =BL18 -> -0.10292958 | O22: =BL15-SUMPRODUCT(G12:G20,L12:L20) -> 0.089300863 | Q22: 44407 | R22: 100.24 | T22: =IF(ISNUMBER(R22),R22/MAX(R22:R$22)-1,"") -> 0 | V22: 592.2 | X22: =IF(ISNUMBER(V22),V22/MAX(V22:V$22)-1,"") -> 0 | Z22: 29.1 | AB22: =IF(ISNUMBER(Z22),Z22/MAX(Z22:Z$22)-1,"") -> 0 | AD22: 15.26 | AF22: =IF(ISNUMBER(AD22),AD22/MAX(AD22:AD$22)-1,"") -> 0 | AH22: 23.099 | AJ22: =IF(ISNUMBER(AH22),AH22/MAX(AH22:AH$22)-1,"") -> 0 | AL22: 49.89 | AN22: =IF(ISNUMBER(AL22),AL22/MAX(AL22:AL$22)-1,"") -> 0 | AP22: 59.51 | AR22: =IF(ISNUMBER(AP22),AP22/MAX(AP22:AP$22)-1,"") -> 0 | AT22: 50.09 | AV22: =IF(ISNUMBER(AT22),AT22/MAX(AT22:AT$22)-1,"") -> 0 | AX22: 306.53 | AZ22: =IF(ISNUMBER(AX22),AX22/MAX(AX22:AX$22)-1,"") -> 0 | BB22: 59.36 | BD22: =IF(ISNUMBER(BB22),BB22/MAX(BB22:BB$22)-1,"") -> 0 | BF22: 53.64 | BH22: =IF(ISNUMBER(BF22),BF22/MAX(BF22:BF$22)-1,"") -> 0 | BJ22: 100 | BL22: =IF(ISNUMBER(BJ22),BJ22/MAX(BJ$22:BJ22)-1,"") -> 0 | BN22: 100 | BP22: =IF(ISNUMBER(BN22),BN22/MAX(BN$22:BN22)-1,"") -> 0 | BR22: 100 | BT22: =IF(ISNUMBER(BR22),BR22/MAX(BR$22:BR22)-1,"") -> 0 | BV22: 45379 | BW22: =BR54/BR51-1 -> 0.11277849 | BX22: =BN54/BN51-1 -> 0.11935626 | BY22: =BJ54/BJ51-1 -> 0.1062284
